2013-03-21 08:21:14,052 [WARNING] django.request: Not Found: /
2013-03-21 08:21:20,610 [WARNING] django.request: Not Found: /ideas
2013-03-21 08:21:31,057 [WARNING] django.request: Not Found: /ideas/ideas
2013-03-21 08:21:39,690 [ERROR] django.request: Internal Server Error: /ideas/submit
Traceback (most recent call last):
  File "/Library/Frameworks/Python.framework/Versions/2.6/lib/python2.6/site-packages/django/core/handlers/base.py", line 89, in get_response
    response = middleware_method(request)
  File "/Library/Frameworks/Python.framework/Versions/2.6/lib/python2.6/site-packages/django/middleware/common.py", line 68, in process_request
    urlresolvers.is_valid_path("%s/" % request.path_info, urlconf)):
  File "/Library/Frameworks/Python.framework/Versions/2.6/lib/python2.6/site-packages/django/core/urlresolvers.py", line 531, in is_valid_path
    resolve(path, urlconf)
  File "/Library/Frameworks/Python.framework/Versions/2.6/lib/python2.6/site-packages/django/core/urlresolvers.py", line 420, in resolve
    return get_resolver(urlconf).resolve(path)
  File "/Library/Frameworks/Python.framework/Versions/2.6/lib/python2.6/site-packages/django/core/urlresolvers.py", line 300, in resolve
    sub_match = pattern.resolve(new_path)
  File "/Library/Frameworks/Python.framework/Versions/2.6/lib/python2.6/site-packages/django/core/urlresolvers.py", line 300, in resolve
    sub_match = pattern.resolve(new_path)
  File "/Library/Frameworks/Python.framework/Versions/2.6/lib/python2.6/site-packages/django/core/urlresolvers.py", line 209, in resolve
    return ResolverMatch(self.callback, args, kwargs, self.name)
  File "/Library/Frameworks/Python.framework/Versions/2.6/lib/python2.6/site-packages/django/core/urlresolvers.py", line 216, in callback
    self._callback = get_callable(self._callback_str)
  File "/Library/Frameworks/Python.framework/Versions/2.6/lib/python2.6/site-packages/django/utils/functional.py", line 27, in wrapper
    result = func(*args)
  File "/Library/Frameworks/Python.framework/Versions/2.6/lib/python2.6/site-packages/django/core/urlresolvers.py", line 92, in get_callable
    lookup_view = getattr(import_module(mod_name), func_name)
  File "/Library/Frameworks/Python.framework/Versions/2.6/lib/python2.6/site-packages/django/utils/importlib.py", line 35, in import_module
    __import__(name)
  File "/Users/brantinghamr/Documents/Code/eclipseWorkspace/iStart/src/iStarter/ideasapp/views.py", line 25, in <module>
    from ideasapp.models import ideaModel
ImportError: cannot import name ideaModel
2013-03-21 08:23:07,611 [ERROR] django.request: Internal Server Error: /ideas/submit
Traceback (most recent call last):
  File "/Library/Frameworks/Python.framework/Versions/2.6/lib/python2.6/site-packages/django/core/handlers/base.py", line 89, in get_response
    response = middleware_method(request)
  File "/Library/Frameworks/Python.framework/Versions/2.6/lib/python2.6/site-packages/django/middleware/common.py", line 68, in process_request
    urlresolvers.is_valid_path("%s/" % request.path_info, urlconf)):
  File "/Library/Frameworks/Python.framework/Versions/2.6/lib/python2.6/site-packages/django/core/urlresolvers.py", line 531, in is_valid_path
    resolve(path, urlconf)
  File "/Library/Frameworks/Python.framework/Versions/2.6/lib/python2.6/site-packages/django/core/urlresolvers.py", line 420, in resolve
    return get_resolver(urlconf).resolve(path)
  File "/Library/Frameworks/Python.framework/Versions/2.6/lib/python2.6/site-packages/django/core/urlresolvers.py", line 300, in resolve
    sub_match = pattern.resolve(new_path)
  File "/Library/Frameworks/Python.framework/Versions/2.6/lib/python2.6/site-packages/django/core/urlresolvers.py", line 300, in resolve
    sub_match = pattern.resolve(new_path)
  File "/Library/Frameworks/Python.framework/Versions/2.6/lib/python2.6/site-packages/django/core/urlresolvers.py", line 209, in resolve
    return ResolverMatch(self.callback, args, kwargs, self.name)
  File "/Library/Frameworks/Python.framework/Versions/2.6/lib/python2.6/site-packages/django/core/urlresolvers.py", line 216, in callback
    self._callback = get_callable(self._callback_str)
  File "/Library/Frameworks/Python.framework/Versions/2.6/lib/python2.6/site-packages/django/utils/functional.py", line 27, in wrapper
    result = func(*args)
  File "/Library/Frameworks/Python.framework/Versions/2.6/lib/python2.6/site-packages/django/core/urlresolvers.py", line 101, in get_callable
    (lookup_view, mod_name))
ViewDoesNotExist: Could not import ideasapp.views.submit. View does not exist in module ideasapp.views.
2013-03-21 08:26:10,177 [ERROR] django.request: Internal Server Error: /ideas/submit/
Traceback (most recent call last):
  File "/Library/Frameworks/Python.framework/Versions/2.6/lib/python2.6/site-packages/django/core/handlers/base.py", line 111, in get_response
    response = callback(request, *callback_args, **callback_kwargs)
  File "/Users/brantinghamr/Documents/Code/eclipseWorkspace/iStart/src/iStarter/ideasapp/views.py", line 78, in submit
    return render_to_response("ideasapp/contact.html", c)
  File "/Library/Frameworks/Python.framework/Versions/2.6/lib/python2.6/site-packages/django/shortcuts/__init__.py", line 20, in render_to_response
    return HttpResponse(loader.render_to_string(*args, **kwargs), **httpresponse_kwargs)
  File "/Library/Frameworks/Python.framework/Versions/2.6/lib/python2.6/site-packages/django/template/loader.py", line 169, in render_to_string
    t = get_template(template_name)
  File "/Library/Frameworks/Python.framework/Versions/2.6/lib/python2.6/site-packages/django/template/loader.py", line 145, in get_template
    template, origin = find_template(template_name)
  File "/Library/Frameworks/Python.framework/Versions/2.6/lib/python2.6/site-packages/django/template/loader.py", line 138, in find_template
    raise TemplateDoesNotExist(name)
TemplateDoesNotExist: ideasapp/contact.html
2013-03-21 08:30:44,490 [WARNING] django.request: Not Found: /docs/prototypes
2013-03-21 08:30:44,700 [WARNING] django.request: Not Found: /favicon.ico
2013-03-21 08:32:10,220 [ERROR] django.request: Internal Server Error: /ideas/submit/
Traceback (most recent call last):
  File "/Library/Frameworks/Python.framework/Versions/2.6/lib/python2.6/site-packages/django/core/handlers/base.py", line 111, in get_response
    response = callback(request, *callback_args, **callback_kwargs)
  File "/Users/brantinghamr/Documents/Code/eclipseWorkspace/iStart/src/iStarter/ideasapp/views.py", line 52, in submit
    user = str(request.user)
  File "/Library/Frameworks/Python.framework/Versions/2.6/lib/python2.6/site-packages/django/utils/functional.py", line 184, in inner
    self._setup()
  File "/Library/Frameworks/Python.framework/Versions/2.6/lib/python2.6/site-packages/django/utils/functional.py", line 248, in _setup
    self._wrapped = self._setupfunc()
  File "/Library/Frameworks/Python.framework/Versions/2.6/lib/python2.6/site-packages/django/contrib/auth/middleware.py", line 16, in <lambda>
    request.user = SimpleLazyObject(lambda: get_user(request))
  File "/Library/Frameworks/Python.framework/Versions/2.6/lib/python2.6/site-packages/django/contrib/auth/middleware.py", line 8, in get_user
    request._cached_user = auth.get_user(request)
  File "/Library/Frameworks/Python.framework/Versions/2.6/lib/python2.6/site-packages/django/contrib/auth/__init__.py", line 98, in get_user
    user_id = request.session[SESSION_KEY]
  File "/Library/Frameworks/Python.framework/Versions/2.6/lib/python2.6/site-packages/django/contrib/sessions/backends/base.py", line 39, in __getitem__
    return self._session[key]
  File "/Library/Frameworks/Python.framework/Versions/2.6/lib/python2.6/site-packages/django/contrib/sessions/backends/base.py", line 165, in _get_session
    self._session_cache = self.load()
  File "/Library/Frameworks/Python.framework/Versions/2.6/lib/python2.6/site-packages/django/contrib/sessions/backends/db.py", line 19, in load
    expire_date__gt=timezone.now()
  File "/Library/Frameworks/Python.framework/Versions/2.6/lib/python2.6/site-packages/django/db/models/manager.py", line 131, in get
    return self.get_query_set().get(*args, **kwargs)
  File "/Library/Frameworks/Python.framework/Versions/2.6/lib/python2.6/site-packages/django/db/models/query.py", line 361, in get
    num = len(clone)
  File "/Library/Frameworks/Python.framework/Versions/2.6/lib/python2.6/site-packages/django/db/models/query.py", line 85, in __len__
    self._result_cache = list(self.iterator())
  File "/Library/Frameworks/Python.framework/Versions/2.6/lib/python2.6/site-packages/django/db/models/query.py", line 291, in iterator
    for row in compiler.results_iter():
  File "/Library/Frameworks/Python.framework/Versions/2.6/lib/python2.6/site-packages/django/db/models/sql/compiler.py", line 763, in results_iter
    for rows in self.execute_sql(MULTI):
  File "/Library/Frameworks/Python.framework/Versions/2.6/lib/python2.6/site-packages/django/db/models/sql/compiler.py", line 818, in execute_sql
    cursor.execute(sql, params)
  File "/Library/Frameworks/Python.framework/Versions/2.6/lib/python2.6/site-packages/django/db/backends/util.py", line 40, in execute
    return self.cursor.execute(sql, params)
  File "/Library/Frameworks/Python.framework/Versions/2.6/lib/python2.6/site-packages/django/db/backends/sqlite3/base.py", line 344, in execute
    return Database.Cursor.execute(self, query, params)
DatabaseError: no such table: django_session
2013-04-07 12:25:28,761 [ERROR] django.request: Internal Server Error: /add/debug/
Traceback (most recent call last):
  File "/var/src/Django-1.4.3/django/core/handlers/base.py", line 111, in get_response
    response = callback(request, *callback_args, **callback_kwargs)
  File "/var/src/Django-1.4.3/django/views/decorators/cache.py", line 89, in _wrapped_view_func
    response = view_func(request, *args, **kwargs)
  File "/var/src/Django-1.4.3/django/contrib/messages/tests/urls.py", line 30, in add
    getattr(messages, message_type)(request, msg)
  File "/var/src/Django-1.4.3/django/contrib/messages/api.py", line 70, in debug
    fail_silently=fail_silently)
  File "/var/src/Django-1.4.3/django/contrib/messages/api.py", line 22, in add_message
    raise MessageFailure('You cannot add messages without installing '
MessageFailure: You cannot add messages without installing django.contrib.messages.middleware.MessageMiddleware
2013-04-07 12:25:28,764 [ERROR] django.request: Internal Server Error: /add/info/
Traceback (most recent call last):
  File "/var/src/Django-1.4.3/django/core/handlers/base.py", line 111, in get_response
    response = callback(request, *callback_args, **callback_kwargs)
  File "/var/src/Django-1.4.3/django/views/decorators/cache.py", line 89, in _wrapped_view_func
    response = view_func(request, *args, **kwargs)
  File "/var/src/Django-1.4.3/django/contrib/messages/tests/urls.py", line 30, in add
    getattr(messages, message_type)(request, msg)
  File "/var/src/Django-1.4.3/django/contrib/messages/api.py", line 78, in info
    fail_silently=fail_silently)
  File "/var/src/Django-1.4.3/django/contrib/messages/api.py", line 22, in add_message
    raise MessageFailure('You cannot add messages without installing '
MessageFailure: You cannot add messages without installing django.contrib.messages.middleware.MessageMiddleware
2013-04-07 12:25:28,767 [ERROR] django.request: Internal Server Error: /add/success/
Traceback (most recent call last):
  File "/var/src/Django-1.4.3/django/core/handlers/base.py", line 111, in get_response
    response = callback(request, *callback_args, **callback_kwargs)
  File "/var/src/Django-1.4.3/django/views/decorators/cache.py", line 89, in _wrapped_view_func
    response = view_func(request, *args, **kwargs)
  File "/var/src/Django-1.4.3/django/contrib/messages/tests/urls.py", line 30, in add
    getattr(messages, message_type)(request, msg)
  File "/var/src/Django-1.4.3/django/contrib/messages/api.py", line 86, in success
    fail_silently=fail_silently)
  File "/var/src/Django-1.4.3/django/contrib/messages/api.py", line 22, in add_message
    raise MessageFailure('You cannot add messages without installing '
MessageFailure: You cannot add messages without installing django.contrib.messages.middleware.MessageMiddleware
2013-04-07 12:25:28,769 [ERROR] django.request: Internal Server Error: /add/warning/
Traceback (most recent call last):
  File "/var/src/Django-1.4.3/django/core/handlers/base.py", line 111, in get_response
    response = callback(request, *callback_args, **callback_kwargs)
  File "/var/src/Django-1.4.3/django/views/decorators/cache.py", line 89, in _wrapped_view_func
    response = view_func(request, *args, **kwargs)
  File "/var/src/Django-1.4.3/django/contrib/messages/tests/urls.py", line 30, in add
    getattr(messages, message_type)(request, msg)
  File "/var/src/Django-1.4.3/django/contrib/messages/api.py", line 94, in warning
    fail_silently=fail_silently)
  File "/var/src/Django-1.4.3/django/contrib/messages/api.py", line 22, in add_message
    raise MessageFailure('You cannot add messages without installing '
MessageFailure: You cannot add messages without installing django.contrib.messages.middleware.MessageMiddleware
2013-04-07 12:25:28,772 [ERROR] django.request: Internal Server Error: /add/error/
Traceback (most recent call last):
  File "/var/src/Django-1.4.3/django/core/handlers/base.py", line 111, in get_response
    response = callback(request, *callback_args, **callback_kwargs)
  File "/var/src/Django-1.4.3/django/views/decorators/cache.py", line 89, in _wrapped_view_func
    response = view_func(request, *args, **kwargs)
  File "/var/src/Django-1.4.3/django/contrib/messages/tests/urls.py", line 30, in add
    getattr(messages, message_type)(request, msg)
  File "/var/src/Django-1.4.3/django/contrib/messages/api.py", line 102, in error
    fail_silently=fail_silently)
  File "/var/src/Django-1.4.3/django/contrib/messages/api.py", line 22, in add_message
    raise MessageFailure('You cannot add messages without installing '
MessageFailure: You cannot add messages without installing django.contrib.messages.middleware.MessageMiddleware
2013-04-07 12:25:28,893 [ERROR] django.request: Internal Server Error: /add/debug/
Traceback (most recent call last):
  File "/var/src/Django-1.4.3/django/core/handlers/base.py", line 111, in get_response
    response = callback(request, *callback_args, **callback_kwargs)
  File "/var/src/Django-1.4.3/django/views/decorators/cache.py", line 89, in _wrapped_view_func
    response = view_func(request, *args, **kwargs)
  File "/var/src/Django-1.4.3/django/contrib/messages/tests/urls.py", line 30, in add
    getattr(messages, message_type)(request, msg)
  File "/var/src/Django-1.4.3/django/contrib/messages/api.py", line 70, in debug
    fail_silently=fail_silently)
  File "/var/src/Django-1.4.3/django/contrib/messages/api.py", line 22, in add_message
    raise MessageFailure('You cannot add messages without installing '
MessageFailure: You cannot add messages without installing django.contrib.messages.middleware.MessageMiddleware
2013-04-07 12:25:28,896 [ERROR] django.request: Internal Server Error: /add/info/
Traceback (most recent call last):
  File "/var/src/Django-1.4.3/django/core/handlers/base.py", line 111, in get_response
    response = callback(request, *callback_args, **callback_kwargs)
  File "/var/src/Django-1.4.3/django/views/decorators/cache.py", line 89, in _wrapped_view_func
    response = view_func(request, *args, **kwargs)
  File "/var/src/Django-1.4.3/django/contrib/messages/tests/urls.py", line 30, in add
    getattr(messages, message_type)(request, msg)
  File "/var/src/Django-1.4.3/django/contrib/messages/api.py", line 78, in info
    fail_silently=fail_silently)
  File "/var/src/Django-1.4.3/django/contrib/messages/api.py", line 22, in add_message
    raise MessageFailure('You cannot add messages without installing '
MessageFailure: You cannot add messages without installing django.contrib.messages.middleware.MessageMiddleware
2013-04-07 12:25:28,899 [ERROR] django.request: Internal Server Error: /add/success/
Traceback (most recent call last):
  File "/var/src/Django-1.4.3/django/core/handlers/base.py", line 111, in get_response
    response = callback(request, *callback_args, **callback_kwargs)
  File "/var/src/Django-1.4.3/django/views/decorators/cache.py", line 89, in _wrapped_view_func
    response = view_func(request, *args, **kwargs)
  File "/var/src/Django-1.4.3/django/contrib/messages/tests/urls.py", line 30, in add
    getattr(messages, message_type)(request, msg)
  File "/var/src/Django-1.4.3/django/contrib/messages/api.py", line 86, in success
    fail_silently=fail_silently)
  File "/var/src/Django-1.4.3/django/contrib/messages/api.py", line 22, in add_message
    raise MessageFailure('You cannot add messages without installing '
MessageFailure: You cannot add messages without installing django.contrib.messages.middleware.MessageMiddleware
2013-04-07 12:25:28,902 [ERROR] django.request: Internal Server Error: /add/warning/
Traceback (most recent call last):
  File "/var/src/Django-1.4.3/django/core/handlers/base.py", line 111, in get_response
    response = callback(request, *callback_args, **callback_kwargs)
  File "/var/src/Django-1.4.3/django/views/decorators/cache.py", line 89, in _wrapped_view_func
    response = view_func(request, *args, **kwargs)
  File "/var/src/Django-1.4.3/django/contrib/messages/tests/urls.py", line 30, in add
    getattr(messages, message_type)(request, msg)
  File "/var/src/Django-1.4.3/django/contrib/messages/api.py", line 94, in warning
    fail_silently=fail_silently)
  File "/var/src/Django-1.4.3/django/contrib/messages/api.py", line 22, in add_message
    raise MessageFailure('You cannot add messages without installing '
MessageFailure: You cannot add messages without installing django.contrib.messages.middleware.MessageMiddleware
2013-04-07 12:25:28,904 [ERROR] django.request: Internal Server Error: /add/error/
Traceback (most recent call last):
  File "/var/src/Django-1.4.3/django/core/handlers/base.py", line 111, in get_response
    response = callback(request, *callback_args, **callback_kwargs)
  File "/var/src/Django-1.4.3/django/views/decorators/cache.py", line 89, in _wrapped_view_func
    response = view_func(request, *args, **kwargs)
  File "/var/src/Django-1.4.3/django/contrib/messages/tests/urls.py", line 30, in add
    getattr(messages, message_type)(request, msg)
  File "/var/src/Django-1.4.3/django/contrib/messages/api.py", line 102, in error
    fail_silently=fail_silently)
  File "/var/src/Django-1.4.3/django/contrib/messages/api.py", line 22, in add_message
    raise MessageFailure('You cannot add messages without installing '
MessageFailure: You cannot add messages without installing django.contrib.messages.middleware.MessageMiddleware
2013-04-07 12:25:29,063 [ERROR] django.request: Internal Server Error: /add/debug/
Traceback (most recent call last):
  File "/var/src/Django-1.4.3/django/core/handlers/base.py", line 111, in get_response
    response = callback(request, *callback_args, **callback_kwargs)
  File "/var/src/Django-1.4.3/django/views/decorators/cache.py", line 89, in _wrapped_view_func
    response = view_func(request, *args, **kwargs)
  File "/var/src/Django-1.4.3/django/contrib/messages/tests/urls.py", line 30, in add
    getattr(messages, message_type)(request, msg)
  File "/var/src/Django-1.4.3/django/contrib/messages/api.py", line 70, in debug
    fail_silently=fail_silently)
  File "/var/src/Django-1.4.3/django/contrib/messages/api.py", line 22, in add_message
    raise MessageFailure('You cannot add messages without installing '
MessageFailure: You cannot add messages without installing django.contrib.messages.middleware.MessageMiddleware
2013-04-07 12:25:29,065 [ERROR] django.request: Internal Server Error: /add/info/
Traceback (most recent call last):
  File "/var/src/Django-1.4.3/django/core/handlers/base.py", line 111, in get_response
    response = callback(request, *callback_args, **callback_kwargs)
  File "/var/src/Django-1.4.3/django/views/decorators/cache.py", line 89, in _wrapped_view_func
    response = view_func(request, *args, **kwargs)
  File "/var/src/Django-1.4.3/django/contrib/messages/tests/urls.py", line 30, in add
    getattr(messages, message_type)(request, msg)
  File "/var/src/Django-1.4.3/django/contrib/messages/api.py", line 78, in info
    fail_silently=fail_silently)
  File "/var/src/Django-1.4.3/django/contrib/messages/api.py", line 22, in add_message
    raise MessageFailure('You cannot add messages without installing '
MessageFailure: You cannot add messages without installing django.contrib.messages.middleware.MessageMiddleware
2013-04-07 12:25:29,067 [ERROR] django.request: Internal Server Error: /add/success/
Traceback (most recent call last):
  File "/var/src/Django-1.4.3/django/core/handlers/base.py", line 111, in get_response
    response = callback(request, *callback_args, **callback_kwargs)
  File "/var/src/Django-1.4.3/django/views/decorators/cache.py", line 89, in _wrapped_view_func
    response = view_func(request, *args, **kwargs)
  File "/var/src/Django-1.4.3/django/contrib/messages/tests/urls.py", line 30, in add
    getattr(messages, message_type)(request, msg)
  File "/var/src/Django-1.4.3/django/contrib/messages/api.py", line 86, in success
    fail_silently=fail_silently)
  File "/var/src/Django-1.4.3/django/contrib/messages/api.py", line 22, in add_message
    raise MessageFailure('You cannot add messages without installing '
MessageFailure: You cannot add messages without installing django.contrib.messages.middleware.MessageMiddleware
2013-04-07 12:25:29,069 [ERROR] django.request: Internal Server Error: /add/warning/
Traceback (most recent call last):
  File "/var/src/Django-1.4.3/django/core/handlers/base.py", line 111, in get_response
    response = callback(request, *callback_args, **callback_kwargs)
  File "/var/src/Django-1.4.3/django/views/decorators/cache.py", line 89, in _wrapped_view_func
    response = view_func(request, *args, **kwargs)
  File "/var/src/Django-1.4.3/django/contrib/messages/tests/urls.py", line 30, in add
    getattr(messages, message_type)(request, msg)
  File "/var/src/Django-1.4.3/django/contrib/messages/api.py", line 94, in warning
    fail_silently=fail_silently)
  File "/var/src/Django-1.4.3/django/contrib/messages/api.py", line 22, in add_message
    raise MessageFailure('You cannot add messages without installing '
MessageFailure: You cannot add messages without installing django.contrib.messages.middleware.MessageMiddleware
2013-04-07 12:25:29,071 [ERROR] django.request: Internal Server Error: /add/error/
Traceback (most recent call last):
  File "/var/src/Django-1.4.3/django/core/handlers/base.py", line 111, in get_response
    response = callback(request, *callback_args, **callback_kwargs)
  File "/var/src/Django-1.4.3/django/views/decorators/cache.py", line 89, in _wrapped_view_func
    response = view_func(request, *args, **kwargs)
  File "/var/src/Django-1.4.3/django/contrib/messages/tests/urls.py", line 30, in add
    getattr(messages, message_type)(request, msg)
  File "/var/src/Django-1.4.3/django/contrib/messages/api.py", line 102, in error
    fail_silently=fail_silently)
  File "/var/src/Django-1.4.3/django/contrib/messages/api.py", line 22, in add_message
    raise MessageFailure('You cannot add messages without installing '
MessageFailure: You cannot add messages without installing django.contrib.messages.middleware.MessageMiddleware
2013-04-07 12:27:49,476 [WARNING] django.request: Not Found: /favicon.ico
2013-04-07 12:27:49,486 [WARNING] django.request: Not Found: /favicon.ico
2013-04-07 12:28:03,674 [WARNING] django.request: Not Found: /docs/technology_credits
2013-04-07 12:40:47,919 [WARNING] django.request: Not Found: /submit
2013-04-07 13:03:35,895 [WARNING] django.request: Not Found: /submit/
2013-04-07 13:14:47,281 [WARNING] django.request: Not Found: /ideas_cloud/
2013-04-07 13:46:46,658 [ERROR] django.request: Internal Server Error: /ideas/ideas_cloud/
Traceback (most recent call last):
  File "/var/src/Django-1.4.3/django/core/handlers/base.py", line 111, in get_response
    response = callback(request, *callback_args, **callback_kwargs)
  File "/home/dusted/iStart/iStart/src/iStarter/ideasapp/views.py", line 93, in ideas_cloud
    c['ideas']=ideasData
  File "/home/dusted/iStart/iStart/src/iStarter/ideasapp/views.py", line 93, in ideas_cloud
    c['ideas']=ideasData
  File "/usr/lib/python2.7/bdb.py", line 48, in trace_dispatch
    return self.dispatch_line(frame)
  File "/usr/lib/python2.7/bdb.py", line 67, in dispatch_line
    if self.quitting: raise BdbQuit
BdbQuit
2013-04-07 14:00:19,758 [ERROR] django.request: Internal Server Error: /ideas/
Traceback (most recent call last):
  File "/var/src/Django-1.4.3/django/core/handlers/base.py", line 111, in get_response
    response = callback(request, *callback_args, **callback_kwargs)
  File "/home/dusted/iStart/iStart/src/iStarter/ideasapp/views.py", line 59, in submit
    idea.save()
  File "/var/src/Django-1.4.3/django/db/models/base.py", line 463, in save
    self.save_base(using=using, force_insert=force_insert, force_update=force_update)
  File "/var/src/Django-1.4.3/django/db/models/base.py", line 551, in save_base
    result = manager._insert([self], fields=fields, return_id=update_pk, using=using, raw=raw)
  File "/var/src/Django-1.4.3/django/db/models/manager.py", line 203, in _insert
    return insert_query(self.model, objs, fields, **kwargs)
  File "/var/src/Django-1.4.3/django/db/models/query.py", line 1593, in insert_query
    return query.get_compiler(using=using).execute_sql(return_id)
  File "/var/src/Django-1.4.3/django/db/models/sql/compiler.py", line 912, in execute_sql
    cursor.execute(sql, params)
  File "/var/src/Django-1.4.3/django/db/backends/util.py", line 40, in execute
    return self.cursor.execute(sql, params)
  File "/var/src/Django-1.4.3/django/db/backends/postgresql_psycopg2/base.py", line 52, in execute
    return self.cursor.execute(query, args)
IntegrityError: null value in column "pub_date" violates not-null constraint

2013-04-07 14:06:40,931 [ERROR] django.request: Internal Server Error: /ideas/
Traceback (most recent call last):
  File "/var/src/Django-1.4.3/django/core/handlers/base.py", line 111, in get_response
    response = callback(request, *callback_args, **callback_kwargs)
  File "/home/dusted/iStart/iStart/src/iStarter/ideasapp/views.py", line 60, in submit
    idea.save()
  File "/var/src/Django-1.4.3/django/db/models/base.py", line 463, in save
    self.save_base(using=using, force_insert=force_insert, force_update=force_update)
  File "/var/src/Django-1.4.3/django/db/models/base.py", line 551, in save_base
    result = manager._insert([self], fields=fields, return_id=update_pk, using=using, raw=raw)
  File "/var/src/Django-1.4.3/django/db/models/manager.py", line 203, in _insert
    return insert_query(self.model, objs, fields, **kwargs)
  File "/var/src/Django-1.4.3/django/db/models/query.py", line 1593, in insert_query
    return query.get_compiler(using=using).execute_sql(return_id)
  File "/var/src/Django-1.4.3/django/db/models/sql/compiler.py", line 912, in execute_sql
    cursor.execute(sql, params)
  File "/var/src/Django-1.4.3/django/db/backends/util.py", line 40, in execute
    return self.cursor.execute(sql, params)
  File "/var/src/Django-1.4.3/django/db/backends/postgresql_psycopg2/base.py", line 52, in execute
    return self.cursor.execute(query, args)
IntegrityError: null value in column "num_backers" violates not-null constraint

2013-04-07 15:20:14,790 [ERROR] django.request: Internal Server Error: /ideas/
Traceback (most recent call last):
  File "/var/src/Django-1.4.3/django/core/handlers/base.py", line 111, in get_response
    response = callback(request, *callback_args, **callback_kwargs)
  File "/home/dusted/iStart/iStart/src/iStarter/ideasapp/views.py", line 61, in submit
    res = saveIdea(cleanForm['title'],cleanForm['description'],cleanForm['cls'])
  File "/home/dusted/iStart/iStart/src/iStarter/ideasapp/code.py", line 68, in saveIdea
    except:
  File "/home/dusted/iStart/iStart/src/iStarter/ideasapp/code.py", line 68, in saveIdea
    except:
  File "/usr/lib/python2.7/bdb.py", line 48, in trace_dispatch
    return self.dispatch_line(frame)
  File "/usr/lib/python2.7/bdb.py", line 67, in dispatch_line
    if self.quitting: raise BdbQuit
BdbQuit
2013-04-07 15:22:59,675 [ERROR] django.request: Internal Server Error: /ideas/
Traceback (most recent call last):
  File "/var/src/Django-1.4.3/django/core/handlers/base.py", line 111, in get_response
    response = callback(request, *callback_args, **callback_kwargs)
  File "/home/dusted/iStart/iStart/src/iStarter/ideasapp/views.py", line 61, in submit
    res = saveIdea(cleanForm['title'],cleanForm['description'],cleanForm['cls'])
  File "/home/dusted/iStart/iStart/src/iStarter/ideasapp/code.py", line 62, in saveIdea
    ideaModel.idea_text = idea_Text
NameError: global name 'idea_Text' is not defined
2013-04-07 15:23:31,364 [ERROR] django.request: Internal Server Error: /ideas/
Traceback (most recent call last):
  File "/var/src/Django-1.4.3/django/core/handlers/base.py", line 111, in get_response
    response = callback(request, *callback_args, **callback_kwargs)
  File "/home/dusted/iStart/iStart/src/iStarter/ideasapp/views.py", line 61, in submit
    res = saveIdea(cleanForm['title'],cleanForm['description'],cleanForm['cls'])
  File "/home/dusted/iStart/iStart/src/iStarter/ideasapp/code.py", line 65, in saveIdea
    ideaModel.save()
TypeError: unbound method save() must be called with idea instance as first argument (got nothing instead)
2013-04-07 15:24:01,627 [ERROR] django.request: Internal Server Error: /ideas/
Traceback (most recent call last):
  File "/var/src/Django-1.4.3/django/core/handlers/base.py", line 111, in get_response
    response = callback(request, *callback_args, **callback_kwargs)
  File "/home/dusted/iStart/iStart/src/iStarter/ideasapp/views.py", line 61, in submit
    res = saveIdea(cleanForm['title'],cleanForm['description'],cleanForm['cls'])
  File "/home/dusted/iStart/iStart/src/iStarter/ideasapp/code.py", line 65, in saveIdea
    ideaModel.idea.save()
AttributeError: type object 'idea' has no attribute 'idea'
2013-04-07 15:29:39,444 [ERROR] django.request: Internal Server Error: /ideas/
Traceback (most recent call last):
  File "/var/src/Django-1.4.3/django/core/handlers/base.py", line 111, in get_response
    response = callback(request, *callback_args, **callback_kwargs)
  File "/home/dusted/iStart/iStart/src/iStarter/ideasapp/views.py", line 61, in submit
    res = saveIdea(cleanForm['title'],cleanForm['description'],cleanForm['cls'])
  File "/home/dusted/iStart/iStart/src/iStarter/ideasapp/code.py", line 60, in saveIdea
    out = ideaModel(idea_title = ideaTitle, pub_date = getDate(), idea_text = ideaText, num_backers = 1, ideaClassification = ideaClassification)
  File "/var/src/Django-1.4.3/django/db/models/base.py", line 367, in __init__
    raise TypeError("'%s' is an invalid keyword argument for this function" % kwargs.keys()[0])
TypeError: 'ideaClassification' is an invalid keyword argument for this function
2013-04-07 15:30:08,731 [ERROR] django.request: Internal Server Error: /ideas/
Traceback (most recent call last):
  File "/var/src/Django-1.4.3/django/core/handlers/base.py", line 111, in get_response
    response = callback(request, *callback_args, **callback_kwargs)
  File "/home/dusted/iStart/iStart/src/iStarter/ideasapp/views.py", line 61, in submit
    res = saveIdea(cleanForm['title'],cleanForm['description'],cleanForm['cls'])
  File "/home/dusted/iStart/iStart/src/iStarter/ideasapp/code.py", line 60, in saveIdea
    out = ideaModel(idea_title = ideaTitle, pub_date = getDate(), idea_text = ideaText, num_backers = 1, idea_Classification = ideaClassification)
  File "/var/src/Django-1.4.3/django/db/models/base.py", line 367, in __init__
    raise TypeError("'%s' is an invalid keyword argument for this function" % kwargs.keys()[0])
TypeError: 'idea_Classification' is an invalid keyword argument for this function
2013-04-07 15:30:34,223 [ERROR] django.request: Internal Server Error: /ideas/
Traceback (most recent call last):
  File "/var/src/Django-1.4.3/django/core/handlers/base.py", line 111, in get_response
    response = callback(request, *callback_args, **callback_kwargs)
  File "/home/dusted/iStart/iStart/src/iStarter/ideasapp/views.py", line 61, in submit
    res = saveIdea(cleanForm['title'],cleanForm['description'],cleanForm['cls'])
  File "/home/dusted/iStart/iStart/src/iStarter/ideasapp/code.py", line 66, in saveIdea
    out.save()
  File "/var/src/Django-1.4.3/django/db/models/base.py", line 463, in save
    self.save_base(using=using, force_insert=force_insert, force_update=force_update)
  File "/var/src/Django-1.4.3/django/db/models/base.py", line 551, in save_base
    result = manager._insert([self], fields=fields, return_id=update_pk, using=using, raw=raw)
  File "/var/src/Django-1.4.3/django/db/models/manager.py", line 203, in _insert
    return insert_query(self.model, objs, fields, **kwargs)
  File "/var/src/Django-1.4.3/django/db/models/query.py", line 1593, in insert_query
    return query.get_compiler(using=using).execute_sql(return_id)
  File "/var/src/Django-1.4.3/django/db/models/sql/compiler.py", line 912, in execute_sql
    cursor.execute(sql, params)
  File "/var/src/Django-1.4.3/django/db/backends/util.py", line 40, in execute
    return self.cursor.execute(sql, params)
  File "/var/src/Django-1.4.3/django/db/backends/postgresql_psycopg2/base.py", line 52, in execute
    return self.cursor.execute(query, args)
IntegrityError: null value in column "idea_id" violates not-null constraint

2013-04-07 15:38:03,344 [ERROR] django.request: Internal Server Error: /ideas/
Traceback (most recent call last):
  File "/var/src/Django-1.4.3/django/core/handlers/base.py", line 111, in get_response
    response = callback(request, *callback_args, **callback_kwargs)
  File "/home/dusted/iStart/iStart/src/iStarter/ideasapp/views.py", line 62, in submit
    res = saveIdea(cleanForm['title'],cleanForm['description'],cleanForm['cls'], idea_headers)
  File "/home/dusted/iStart/iStart/src/iStarter/ideasapp/code.py", line 60, in saveIdea
    out = ideaModel(idea_title = ideaTitle, pub_date = getDate(), idea_text = ideaText, num_backers = 1, idea_classification = ideaClassification, idea_headers = idea_Headers)
NameError: global name 'idea_Headers' is not defined
2013-04-07 15:39:29,383 [ERROR] django.request: Internal Server Error: /ideas/ideas_cloud/
Traceback (most recent call last):
  File "/var/src/Django-1.4.3/django/core/handlers/base.py", line 111, in get_response
    response = callback(request, *callback_args, **callback_kwargs)
  File "/home/dusted/iStart/iStart/src/iStarter/ideasapp/views.py", line 95, in ideas_cloud
    return render_to_response("ideasapp/ideas_cloud.html", c)
  File "/var/src/Django-1.4.3/django/shortcuts/__init__.py", line 20, in render_to_response
    return HttpResponse(loader.render_to_string(*args, **kwargs), **httpresponse_kwargs)
  File "/var/src/Django-1.4.3/django/template/loader.py", line 171, in render_to_string
    return t.render(Context(dictionary))
  File "/var/src/Django-1.4.3/django/template/base.py", line 140, in render
    return self._render(context)
  File "/var/src/Django-1.4.3/django/template/base.py", line 134, in _render
    return self.nodelist.render(context)
  File "/var/src/Django-1.4.3/django/template/base.py", line 823, in render
    bit = self.render_node(node, context)
  File "/var/src/Django-1.4.3/django/template/debug.py", line 74, in render_node
    return node.render(context)
  File "/var/src/Django-1.4.3/django/template/loader_tags.py", line 123, in render
    return compiled_parent._render(context)
  File "/var/src/Django-1.4.3/django/template/base.py", line 134, in _render
    return self.nodelist.render(context)
  File "/var/src/Django-1.4.3/django/template/base.py", line 823, in render
    bit = self.render_node(node, context)
  File "/var/src/Django-1.4.3/django/template/debug.py", line 74, in render_node
    return node.render(context)
  File "/var/src/Django-1.4.3/django/template/loader_tags.py", line 62, in render
    result = block.nodelist.render(context)
  File "/var/src/Django-1.4.3/django/template/base.py", line 823, in render
    bit = self.render_node(node, context)
  File "/var/src/Django-1.4.3/django/template/debug.py", line 74, in render_node
    return node.render(context)
  File "/var/src/Django-1.4.3/django/template/debug.py", line 87, in render
    output = force_unicode(output)
  File "/var/src/Django-1.4.3/django/utils/encoding.py", line 74, in force_unicode
    s = unicode(str(s), encoding, errors)
  File "/var/src/Django-1.4.3/django/db/models/query.py", line 75, in __repr__
    return repr(data)
  File "/var/src/Django-1.4.3/django/db/models/base.py", line 373, in __repr__
    u = unicode(self)
  File "/home/dusted/iStart/iStart/src/iStarter/ideasapp/models.py", line 7, in __unicode__
    return self.title
AttributeError: 'idea' object has no attribute 'title'
2013-04-07 15:44:17,630 [ERROR] django.request: Internal Server Error: /ideas/ideas_cloud/
Traceback (most recent call last):
  File "/var/src/Django-1.4.3/django/core/handlers/base.py", line 111, in get_response
    response = callback(request, *callback_args, **callback_kwargs)
  File "/home/dusted/iStart/iStart/src/iStarter/ideasapp/views.py", line 92, in ideas_cloud
    ideasData = ideasCloud()
  File "/home/dusted/iStart/iStart/src/iStarter/ideasapp/code.py", line 52, in ideasCloud
    return data
  File "/home/dusted/iStart/iStart/src/iStarter/ideasapp/code.py", line 52, in ideasCloud
    return data
  File "/usr/lib/python2.7/bdb.py", line 48, in trace_dispatch
    return self.dispatch_line(frame)
  File "/usr/lib/python2.7/bdb.py", line 67, in dispatch_line
    if self.quitting: raise BdbQuit
BdbQuit
2013-04-07 15:51:34,612 [ERROR] django.request: Internal Server Error: /ideas/ideas_cloud/
Traceback (most recent call last):
  File "/var/src/Django-1.4.3/django/core/handlers/base.py", line 111, in get_response
    response = callback(request, *callback_args, **callback_kwargs)
  File "/home/dusted/iStart/iStart/src/iStarter/ideasapp/views.py", line 92, in ideas_cloud
    ideasData = ideasCloud()
  File "/home/dusted/iStart/iStart/src/iStarter/ideasapp/code.py", line 51, in ideasCloud
    data = ideaModel.objects.all()
  File "/home/dusted/iStart/iStart/src/iStarter/ideasapp/code.py", line 51, in ideasCloud
    data = ideaModel.objects.all()
  File "/usr/lib/python2.7/bdb.py", line 48, in trace_dispatch
    return self.dispatch_line(frame)
  File "/usr/lib/python2.7/bdb.py", line 67, in dispatch_line
    if self.quitting: raise BdbQuit
BdbQuit
2013-04-07 16:53:32,593 [WARNING] django.request: Not Found: /ideas/ideas_list.html
2013-04-07 16:59:55,312 [ERROR] django.request: Internal Server Error: /ideas/ideas_list/
Traceback (most recent call last):
  File "/var/src/Django-1.4.3/django/core/handlers/base.py", line 101, in get_response
    request.path_info)
  File "/var/src/Django-1.4.3/django/core/urlresolvers.py", line 300, in resolve
    sub_match = pattern.resolve(new_path)
  File "/var/src/Django-1.4.3/django/core/urlresolvers.py", line 300, in resolve
    sub_match = pattern.resolve(new_path)
  File "/var/src/Django-1.4.3/django/core/urlresolvers.py", line 209, in resolve
    return ResolverMatch(self.callback, args, kwargs, self.name)
  File "/var/src/Django-1.4.3/django/core/urlresolvers.py", line 216, in callback
    self._callback = get_callable(self._callback_str)
  File "/var/src/Django-1.4.3/django/utils/functional.py", line 27, in wrapper
    result = func(*args)
  File "/var/src/Django-1.4.3/django/core/urlresolvers.py", line 92, in get_callable
    lookup_view = getattr(import_module(mod_name), func_name)
  File "/var/src/Django-1.4.3/django/utils/importlib.py", line 35, in import_module
    __import__(name)
  File "/home/dusted/iStart/iStart/src/iStarter/ideasapp/views.py", line 104
    c['headings']="<th>1</th><th>2</th><th>3</th>"
    ^
SyntaxError: invalid syntax
2013-04-07 17:11:52,080 [ERROR] django.request: Internal Server Error: /ideas/ideas_list/
Traceback (most recent call last):
  File "/var/src/Django-1.4.3/django/core/handlers/base.py", line 111, in get_response
    response = callback(request, *callback_args, **callback_kwargs)
  File "/home/dusted/iStart/iStart/src/iStarter/ideasapp/views.py", line 107, in ideas_list
    return render_to_response("ideasapp/ideas_list.html", c)
  File "/var/src/Django-1.4.3/django/shortcuts/__init__.py", line 20, in render_to_response
    return HttpResponse(loader.render_to_string(*args, **kwargs), **httpresponse_kwargs)
  File "/var/src/Django-1.4.3/django/template/loader.py", line 169, in render_to_string
    t = get_template(template_name)
  File "/var/src/Django-1.4.3/django/template/loader.py", line 145, in get_template
    template, origin = find_template(template_name)
  File "/var/src/Django-1.4.3/django/template/loader.py", line 134, in find_template
    source, display_name = loader(name, dirs)
  File "/var/src/Django-1.4.3/django/template/loader.py", line 42, in __call__
    return self.load_template(template_name, template_dirs)
  File "/var/src/Django-1.4.3/django/template/loader.py", line 48, in load_template
    template = get_template_from_string(source, origin, template_name)
  File "/var/src/Django-1.4.3/django/template/loader.py", line 156, in get_template_from_string
    return Template(source, origin, name)
  File "/var/src/Django-1.4.3/django/template/base.py", line 125, in __init__
    self.nodelist = compile_string(template_string, origin)
  File "/var/src/Django-1.4.3/django/template/base.py", line 153, in compile_string
    return parser.parse()
  File "/var/src/Django-1.4.3/django/template/base.py", line 267, in parse
    compiled_result = compile_func(self, token)
  File "/var/src/Django-1.4.3/django/template/loader_tags.py", line 214, in do_extends
    nodelist = parser.parse()
  File "/var/src/Django-1.4.3/django/template/base.py", line 267, in parse
    compiled_result = compile_func(self, token)
  File "/var/src/Django-1.4.3/django/template/loader_tags.py", line 189, in do_block
    nodelist = parser.parse(('endblock',))
  File "/var/src/Django-1.4.3/django/template/base.py", line 267, in parse
    compiled_result = compile_func(self, token)
  File "/var/src/Django-1.4.3/django/template/defaulttags.py", line 762, in do_for
    nodelist_loop = parser.parse(('empty', 'endfor',))
  File "/var/src/Django-1.4.3/django/template/base.py", line 267, in parse
    compiled_result = compile_func(self, token)
  File "/var/src/Django-1.4.3/django/template/defaulttags.py", line 762, in do_for
    nodelist_loop = parser.parse(('empty', 'endfor',))
  File "/var/src/Django-1.4.3/django/template/base.py", line 265, in parse
    self.invalid_block_tag(token, command, parse_until)
  File "/var/src/Django-1.4.3/django/template/base.py", line 320, in invalid_block_tag
    (command, get_text_list(["'%s'" % p for p in parse_until])))
TemplateSyntaxError: Invalid block tag: 'endblock', expected 'empty' or 'endfor'
2013-04-07 17:31:23,776 [ERROR] django.request: Internal Server Error: /ideas/ideas_cloud/
Traceback (most recent call last):
  File "/var/src/Django-1.4.3/django/core/handlers/base.py", line 101, in get_response
    request.path_info)
  File "/var/src/Django-1.4.3/django/core/urlresolvers.py", line 300, in resolve
    sub_match = pattern.resolve(new_path)
  File "/var/src/Django-1.4.3/django/core/urlresolvers.py", line 300, in resolve
    sub_match = pattern.resolve(new_path)
  File "/var/src/Django-1.4.3/django/core/urlresolvers.py", line 209, in resolve
    return ResolverMatch(self.callback, args, kwargs, self.name)
  File "/var/src/Django-1.4.3/django/core/urlresolvers.py", line 216, in callback
    self._callback = get_callable(self._callback_str)
  File "/var/src/Django-1.4.3/django/utils/functional.py", line 27, in wrapper
    result = func(*args)
  File "/var/src/Django-1.4.3/django/core/urlresolvers.py", line 92, in get_callable
    lookup_view = getattr(import_module(mod_name), func_name)
  File "/var/src/Django-1.4.3/django/utils/importlib.py", line 35, in import_module
    __import__(name)
  File "/home/dusted/iStart/iStart/src/iStarter/ideasapp/views.py", line 26, in <module>
    from code import formatSubmitterEmail, formatHttpHeaders, ideasCloud, getDate, saveIdea
  File "/home/dusted/iStart/iStart/src/iStarter/ideasapp/code.py", line 68
    for
       ^
SyntaxError: invalid syntax
2013-04-07 19:12:01,187 [WARNING] django.request: Not Found: /ideas/ideas_list.html
2013-04-07 19:12:02,610 [WARNING] django.request: Not Found: /ideas/ideas_list.html
2013-04-07 19:12:17,029 [WARNING] django.request: Not Found: /ideas/ideas_list.html
2013-04-07 19:12:21,018 [WARNING] django.request: Not Found: /ideas/ideas_list.html
